Workbook

Sheet data
A1: SKU | B1: ProductName | C1: Category | D1: CurrentStock | E1: ReorderPoint | F1: DailySalesAvg | G1: LeadTime | H1: SupplierID | I1: LastRestockDate | J1: UnitPrice | K1: SnapshotDate
A2: SKU-016 | B2: Parfum EDT Brasov 100ml | C2: Beauty | D2: 271 | E2: 50 | F2: 2 | G2: 4 | H2: SUP_BT02 | I2: 45748 | J2: 125000 | K2: 45748
A3: SKU-001 | B3: Laptop ASUS Vivobook | C3: Electronics | D3: 21 | E3: 15 | F3: 4 | G3: 5 | H3: SUP_EL01 | I3: 45942 | J3: 8500000 | K3: 45931
A4: SKU-004 | B4: Smartwatch Xiaomi Band | C4: Electronics | D4: 30 | E4: 30 | F4: 2 | G4: 7 | H4: SUP_EL01 | I4: 46029 | J4: 1200000 | K4: 46023
A5: SKU-005 | B5: Kemeja Formal Pria | C5: Fashion | D5: 25 | E5: 50 | F5: 6 | G5: 3 | H5: SUP_FA01 | I5: 45688 | J5: 350000 | K5: 45658
A6: SKU-002 | B6: Smartphone Samsung A54 | C6: Electronics | D6: 0 | E6: 25 | F6: 7 | G6: 21 | H6: SUP_EL02 | I6: 45978 | J6: 4500000 | K6: 45962
A7: SKU-005 | B7: Kemeja Formal Pria | C7: Fashion | D7: 0 | E7: 50 | F7: 11 | G7: 7 | H7: SUP_FA01 | I7: 45749 | J7: 350000 | K7: 45748
A8: SKU-007 | B8: Sepatu Sneakers Nike | C8: Fashion | D8: 0 | E8: 35 | F8: 8 | G8: 5 | H8: SUP_FA02 | I8: 45774 | J8: 1250000 | K8: 45748
A9: SKU-013 | B9: Skincare Set Whitelab | C9: Beauty | D9: 220 | E9: 40 | F9: 2 | G9: 5 | H9: SUP_BT01 | I9: 45831 | J9: 550000 | K9: 45809
A10: SKU-018 | B10: Teh Organik Premium Box | C10: Food & Beverage | D10: 28 | E10: 80 | F10: 11 | G10: 4 | H10: SUP_FB01 | I10: 45812 | J10: 65000 | K10: 45809
A11: SKU-004 | B11: Smartwatch Xiaomi Band | C11: Electronics | D11: 24 | E11: 30 | F11: 3 | G11: 6 | H11: SUP_EL01 | I11: 45695 | J11: 1200000 | K11: 45689
A12: SKU-006 | B12: Dress Casual Wanita | C12: Fashion | D12: -28 | E12: 45 | F12: 7 | G12: 5 | H12: SUP_FA01 | I12: 45664 | J12: 450000 | K12: 45658
A13: SKU-011 | B13: Vacuum Cleaner Deerma | C13: Home & Living | D13: -18 | E13: 15 | F13: 4 | G13: 6 | H13: SUP_HM02 | I13: 46099 | J13: 1200000 | K13: 46082
... A76: SKU-002 | B76: Smartphone Samsung A54 | C76: Electronics | D76: 42 | E76: 25 | F76: 4 | G76: 19 | H76: SUP_EL02 | I76: 45881 | J76: 4500000 | K76: 45870
A77: SKU-019 | B77: Madu Hutan Asli 500ml | C77: Food & Beverage | D77: 18 | E77: 60 | F77: 8 | G77: 5 | H77: SUP_FB02 | I77: 45712 | K77: 45689
A78: SKU-004 | B78: Smartwatch Xiaomi Band | C78: Electronics | D78: 17 | E78: 30 | F78: 6 | G78: 8 | H78: SUP_EL01 | I78: 45996 | J78: 1200000 | K78: 45992
A79: SKU-016 | B79: Parfum EDT Brasov 100ml | C79: Beauty | D79: 238 | E79: 50 | F79: 2 | G79: 7 | H79: SUP_BT02 | I79: 45671 | J79: 125000 | K79: 45658
A80: SKU-008 | B80: Tas Ransel Eiger | C80: Fashion | D80: 0 | E80: 40 | F80: 10 | G80: 7 | H80: SUP_FA02 | I80: 46109 | J80: 550000 | K80: 46082
A81: SKU-018 | B81: Teh Organik Premium Box | C81: Food & Beverage | E81: 80 | F81: 11 | G81: 4 | H81: SUP_FB01 | I81: 45766 | J81: 65000 | K81: 45748
A82: SKU-017 | B82: Kopi Arabika 250g Pack | C82: Food & Beverage | D82: 26 | E82: 100 | F82: 16 | G82: 4 | H82: SUP_FB01 | I82: 45778 | J82: 85000 | K82: 45778
A83: SKU-014 | B83: Lipstik Matte Wardah | C83: Beauty | D83: 301 | E83: 80 | F83: 3 | G83: 4 | H83: SUP_BT01 | I83: 45936 | J83: 85000 | K83: 45931
A84: SKU-010 | B84: Rice Cooker Miyako 1.8L | C84: Home & Living | D84: 19 | E84: 25 | F84: 4 | G84: 10 | H84: SUP_HM01 | I84: 45729 | J84: 450000 | K84: 45717
A85: SKU-012 | B85: Kipas Angin Cosmos 16in | C85: Home & Living | D85: 51 | E85: 30 | F85: 6 | G85: 9 | H85: SUP_HM02 | I85: 45752 | J85: 350000 | K85: 45748
A86: SKU-007 | B86: Sepatu Sneakers Nike | C86: Fashion | D86: 17 | E86: 35 | F86: 5 | G86: 5 | H86: SUP_FA02 | I86: 45663 | J86: 1250000 | K86: 45658
A87: SKU-015 | B87: Foundation Maybelline Fit | C87: Beauty | D87: 223 | E87: 60 | F87: 4 | G87: 8 | H87: SUP_BT02 | I87: 46108 | J87: 165000 | K87: 46082
A88: SKU-005 | B88: Kemeja Formal Pria | C88: Fashion | D88: 34 | E88: 50 | F88: 6 | G88: 6 | H88: SUP_FA01 | I88: 45849 | J88: 350000 | K88: 45839
A89: SKU-008 | B89: Tas Ransel Eiger | C89: Fashion | D89: 10 | E89: 40 | F89: 4 | G89: 3 | H89: SUP_FA02 | I89: 46055 | J89: 550000 | K89: 46054
A90: SKU-014 | B90: Lipstik Matte Wardah | C90: Beauty | D90: 436 | E90: 80 | F90: 4 | G90: 4 | H90: SUP_BT01 | I90: 45755 | J90: 85000 | K90: 45748
A91: SKU-002 | B91: Smartphone Samsung A54 | C91: Electronics | D91: 0 | E91: 25 | F91: 8 | G91: 10 | H91: SUP_EL02 | I91: 46013 | J91: 4500000 | K91: 45992
A92: SKU-002 | B92: Smartphone Samsung A54 | C92: Electronics | D92: 20 | E92: 25 | F92: 4 | G92: 19 | H92: SUP_EL02 | I92: 45786 | J92: 4500000 | K92: 45778
A93: SKU-010 | B93: Rice Cooker Miyako 1.8L | C93: Home & Living | D93: 42 | E93: 25 | F93: 4 | G93: 8 | H93: SUP_HM01 | I93: 46029 | J93: 450000 | K93: 46023
... A122: SKU-007 | B122: Sepatu Sneakers Nike | C122: Fashion | D122: 18 | E122: 35 | F122: 7 | G122: 5 | H122: SUP_FA02 | I122: 45859 | J122: 1250000 | K122: 45839
A123: SKU-010 | B123: Rice Cooker Miyako 1.8L | C123: Home & Living | D123: 14 | E123: 25 | F123: 5 | G123: 9 | H123: SUP_HM01 | I123: 45816 | K123: 45809
A124: SKU-012 | B124: Kipas Angin Cosmos 16in | C124: Home & Living | D124: 34 | E124: 30 | F124: 5 | G124: 5 | H124: SUP_HM02 | I124: 46007 | J124: 350000 | K124: 45992
A125: SKU-006 | B125: Dress Casual Wanita | C125: Fashion | D125: 0 | E125: 45 | F125: 13 | G125: 7 | H125: SUP_FA01 | I125: 46015 | J125: 450000 | K125: 45992
A126: SKU-018 | B126: Teh Organik Premium Box | C126: Food & Beverage | D126: 17 | E126: 80 | F126: 11 | G126: 5 | H126: SUP_FB01 | I126: 45882 | J126: 65000 | K126: 45870
A127: SKU-019 | B127: Madu Hutan Asli 500ml | C127: Food & Beverage | D127: 0 | E127: 60 | F127: 14 | G127: 4 | H127: SUP_FB02 | I127: 45741 | J127: 175000 | K127: 45717
A128: SKU-011 | B128: Vacuum Cleaner Deerma | C128: Home & Living | D128: 13 | E128: 15 | F128: 2 | G128: 7 | H128: SUP_HM02 | I128: 45799 | J128: 1200000 | K128: 45778
A129: SKU-018 | B129: Teh Organik Premium Box | C129: Food & Beverage | D129: 9 | E129: 80 | F129: 11 | G129: 4 | H129: SUP_FB01 | I129: 46077 | J129: 65000 | K129: 46054
A130: SKU-015 | B130: Foundation Maybelline Fit | C130: Beauty | D130: 202 | E130: 60 | F130: 2 | G130: 4 | H130: SUP_BT02 | I130: 46019 | J130: 165000 | K130: 45992
...

Sheet Sheet12
A1: SKU | B1: ProductName | C1: Category | D1: CurrentStock | E1: ReorderPoint | F1: DailySalesAvg | G1: LeadTime | H1: SupplierID | I1: LastRestockDate | J1: UnitPrice | K1: SnapshotDate
A2: SKU-016 | B2: Parfum EDT Brasov 100ml | C2: Beauty | D2: 271 | E2: 50 | F2: 2 | G2: 4 | H2: SUP_BT02 | I2: 45748 | J2: 125000 | K2: 45748
A3: SKU-001 | B3: Laptop ASUS Vivobook | C3: Electronics | D3: 21 | E3: 15 | F3: 4 | G3: 5 | H3: SUP_EL01 | I3: 45942 | J3: 8500000 | K3: 45931
A4: SKU-004 | B4: Smartwatch Xiaomi Band | C4: Electronics | D4: 30 | E4: 30 | F4: 2 | G4: 7 | H4: SUP_EL01 | I4: 46029 | J4: 1200000 | K4: 46023
A5: SKU-005 | B5: Kemeja Formal Pria | C5: Fashion | D5: 25 | E5: 50 | F5: 6 | G5: 3 | H5: SUP_FA01 | I5: 45688 | J5: 350000 | K5: 45658
A6: SKU-002 | B6: Smartphone Samsung A54 | C6: Electronics | D6: 0 | E6: 25 | F6: 7 | G6: 21 | H6: SUP_EL02 | I6: 45978 | J6: 4500000 | K6: 45962
A7: SKU-005 | B7: Kemeja Formal Pria | C7: Fashion | D7: 0 | E7: 50 | F7: 11 | G7: 7 | H7: SUP_FA01 | I7: 45749 | J7: 350000 | K7: 45748
A8: SKU-007 | B8: Sepatu Sneakers Nike | C8: Fashion | D8: 0 | E8: 35 | F8: 8 | G8: 5 | H8: SUP_FA02 | I8: 45774 | J8: 1250000 | K8: 45748
A9: SKU-013 | B9: Skincare Set Whitelab | C9: Beauty | D9: 220 | E9: 40 | F9: 2 | G9: 5 | H9: SUP_BT01 | I9: 45831 | J9: 550000 | K9: 45809
A10: SKU-018 | B10: Teh Organik Premium Box | C10: Food & Beverage | D10: 28 | E10: 80 | F10: 11 | G10: 4 | H10: SUP_FB01 | I10: 45812 | J10: 65000 | K10: 45809
A11: SKU-004 | B11: Smartwatch Xiaomi Band | C11: Electronics | D11: 24 | E11: 30 | F11: 3 | G11: 6 | H11: SUP_EL01 | I11: 45695 | J11: 1200000 | K11: 45689
A12: SKU-006 | B12: Dress Casual Wanita | C12: Fashion | D12: -28 | E12: 45 | F12: 7 | G12: 5 | H12: SUP_FA01 | I12: 45664 | J12: 450000 | K12: 45658
A13: SKU-011 | B13: Vacuum Cleaner Deerma | C13: Home & Living | D13: -18 | E13: 15 | F13: 4 | G13: 6 | H13: SUP_HM02 | I13: 46099 | J13: 1200000 | K13: 46082
... A76: SKU-002 | B76: Smartphone Samsung A54 | C76: Electronics | D76: 42 | E76: 25 | F76: 4 | G76: 19 | H76: SUP_EL02 | I76: 45881 | J76: 4500000 | K76: 45870
A77: SKU-019 | B77: Madu Hutan Asli 500ml | C77: Food & Beverage | D77: 18 | E77: 60 | F77: 8 | G77: 5 | H77: SUP_FB02 | I77: 45712 | K77: 45689
A78: SKU-004 | B78: Smartwatch Xiaomi Band | C78: Electronics | D78: 17 | E78: 30 | F78: 6 | G78: 8 | H78: SUP_EL01 | I78: 45996 | J78: 1200000 | K78: 45992
A79: SKU-016 | B79: Parfum EDT Brasov 100ml | C79: Beauty | D79: 238 | E79: 50 | F79: 2 | G79: 7 | H79: SUP_BT02 | I79: 45671 | J79: 125000 | K79: 45658
A80: SKU-008 | B80: Tas Ransel Eiger | C80: Fashion | D80: 0 | E80: 40 | F80: 10 | G80: 7 | H80: SUP_FA02 | I80: 46109 | J80: 550000 | K80: 46082
A81: SKU-018 | B81: Teh Organik Premium Box | C81: Food & Beverage | E81: 80 | F81: 11 | G81: 4 | H81: SUP_FB01 | I81: 45766 | J81: 65000 | K81: 45748
A82: SKU-017 | B82: Kopi Arabika 250g Pack | C82: Food & Beverage | D82: 26 | E82: 100 | F82: 16 | G82: 4 | H82: SUP_FB01 | I82: 45778 | J82: 85000 | K82: 45778
A83: SKU-014 | B83: Lipstik Matte Wardah | C83: Beauty | D83: 301 | E83: 80 | F83: 3 | G83: 4 | H83: SUP_BT01 | I83: 45936 | J83: 85000 | K83: 45931
A84: SKU-010 | B84: Rice Cooker Miyako 1.8L | C84: Home & Living | D84: 19 | E84: 25 | F84: 4 | G84: 10 | H84: SUP_HM01 | I84: 45729 | J84: 450000 | K84: 45717
A85: SKU-012 | B85: Kipas Angin Cosmos 16in | C85: Home & Living | D85: 51 | E85: 30 | F85: 6 | G85: 9 | H85: SUP_HM02 | I85: 45752 | J85: 350000 | K85: 45748
A86: SKU-007 | B86: Sepatu Sneakers Nike | C86: Fashion | D86: 17 | E86: 35 | F86: 5 | G86: 5 | H86: SUP_FA02 | I86: 45663 | J86: 1250000 | K86: 45658
A87: SKU-015 | B87: Foundation Maybelline Fit | C87: Beauty | D87: 223 | E87: 60 | F87: 4 | G87: 8 | H87: SUP_BT02 | I87: 46108 | J87: 165000 | K87: 46082
A88: SKU-005 | B88: Kemeja Formal Pria | C88: Fashion | D88: 34 | E88: 50 | F88: 6 | G88: 6 | H88: SUP_FA01 | I88: 45849 | J88: 350000 | K88: 45839
A89: SKU-008 | B89: Tas Ransel Eiger | C89: Fashion | D89: 10 | E89: 40 | F89: 4 | G89: 3 | H89: SUP_FA02 | I89: 46055 | J89: 550000 | K89: 46054
A90: SKU-014 | B90: Lipstik Matte Wardah | C90: Beauty | D90: 436 | E90: 80 | F90: 4 | G90: 4 | H90: SUP_BT01 | I90: 45755 | J90: 85000 | K90: 45748
A91: SKU-002 | B91: Smartphone Samsung A54 | C91: Electronics | D91: 0 | E91: 25 | F91: 8 | G91: 10 | H91: SUP_EL02 | I91: 46013 | J91: 4500000 | K91: 45992
A92: SKU-002 | B92: Smartphone Samsung A54 | C92: Electronics | D92: 20 | E92: 25 | F92: 4 | G92: 19 | H92: SUP_EL02 | I92: 45786 | J92: 4500000 | K92: 45778
A93: SKU-010 | B93: Rice Cooker Miyako 1.8L | C93: Home & Living | D93: 42 | E93: 25 | F93: 4 | G93: 8 | H93: SUP_HM01 | I93: 46029 | J93: 450000 | K93: 46023
... A122: SKU-007 | B122: Sepatu Sneakers Nike | C122: Fashion | D122: 18 | E122: 35 | F122: 7 | G122: 5 | H122: SUP_FA02 | I122: 45859 | J122: 1250000 | K122: 45839
A123: SKU-010 | B123: Rice Cooker Miyako 1.8L | C123: Home & Living | D123: 14 | E123: 25 | F123: 5 | G123: 9 | H123: SUP_HM01 | I123: 45816 | K123: 45809
A124: SKU-012 | B124: Kipas Angin Cosmos 16in | C124: Home & Living | D124: 34 | E124: 30 | F124: 5 | G124: 5 | H124: SUP_HM02 | I124: 46007 | J124: 350000 | K124: 45992
A125: SKU-006 | B125: Dress Casual Wanita | C125: Fashion | D125: 0 | E125: 45 | F125: 13 | G125: 7 | H125: SUP_FA01 | I125: 46015 | J125: 450000 | K125: 45992
A126: SKU-018 | B126: Teh Organik Premium Box | C126: Food & Beverage | D126: 17 | E126: 80 | F126: 11 | G126: 5 | H126: SUP_FB01 | I126: 45882 | J126: 65000 | K126: 45870
A127: SKU-019 | B127: Madu Hutan Asli 500ml | C127: Food & Beverage | D127: 0 | E127: 60 | F127: 14 | G127: 4 | H127: SUP_FB02 | I127: 45741 | J127: 175000 | K127: 45717
A128: SKU-011 | B128: Vacuum Cleaner Deerma | C128: Home & Living | D128: 13 | E128: 15 | F128: 2 | G128: 7 | H128: SUP_HM02 | I128: 45799 | J128: 1200000 | K128: 45778
A129: SKU-018 | B129: Teh Organik Premium Box | C129: Food & Beverage | D129: 9 | E129: 80 | F129: 11 | G129: 4 | H129: SUP_FB01 | I129: 46077 | J129: 65000 | K129: 46054
A130: SKU-015 | B130: Foundation Maybelline Fit | C130: Beauty | D130: 202 | E130: 60 | F130: 2 | G130: 4 | H130: SUP_BT02 | I130: 46019 | J130: 165000 | K130: 45992
...

Sheet Sheet3
A1: SKU | B1: ProductName | C1: Category | D1: CurrentStock | E1: ReorderPoint | F1: DailySalesAvg | G1: LeadTime | H1: SupplierID | I1: LastRestockDate | J1: UnitPrice | K1: SnapshotDate
A2: SKU-016 | B2: Parfum EDT Brasov 100ml | C2: Beauty | D2: 271 | E2: 50 | F2: 2 | G2: 4 | H2: SUP_BT02 | I2: 45748 | J2: 125000 | K2: 45748
A3: SKU-001 | B3: Laptop ASUS Vivobook | C3: Electronics | D3: 21 | E3: 15 | F3: 4 | G3: 5 | H3: SUP_EL01 | I3: 45942 | J3: 8500000 | K3: 45931
A4: SKU-004 | B4: Smartwatch Xiaomi Band | C4: Electronics | D4: 30 | E4: 30 | F4: 2 | G4: 7 | H4: SUP_EL01 | I4: 46029 | J4: 1200000 | K4: 46023
A5: SKU-005 | B5: Kemeja Formal Pria | C5: Fashion | D5: 25 | E5: 50 | F5: 6 | G5: 3 | H5: SUP_FA01 | I5: 45688 | J5: 350000 | K5: 45658
A6: SKU-002 | B6: Smartphone Samsung A54 | C6: Electronics | D6: 0 | E6: 25 | F6: 7 | G6: 21 | H6: SUP_EL02 | I6: 45978 | J6: 4500000 | K6: 45962
A7: SKU-005 | B7: Kemeja Formal Pria | C7: Fashion | D7: 0 | E7: 50 | F7: 11 | G7: 7 | H7: SUP_FA01 | I7: 45749 | J7: 350000 | K7: 45748
A8: SKU-007 | B8: Sepatu Sneakers Nike | C8: Fashion | D8: 0 | E8: 35 | F8: 8 | G8: 5 | H8: SUP_FA02 | I8: 45774 | J8: 1250000 | K8: 45748
A9: SKU-013 | B9: Skincare Set Whitelab | C9: Beauty | D9: 220 | E9: 40 | F9: 2 | G9: 5 | H9: SUP_BT01 | I9: 45831 | J9: 550000 | K9: 45809
A10: SKU-018 | B10: Teh Organik Premium Box | C10: Food & Beverage | D10: 28 | E10: 80 | F10: 11 | G10: 4 | H10: SUP_FB01 | I10: 45812 | J10: 65000 | K10: 45809
A11: SKU-004 | B11: Smartwatch Xiaomi Band | C11: Electronics | D11: 24 | E11: 30 | F11: 3 | G11: 6 | H11: SUP_EL01 | I11: 45695 | J11: 1200000 | K11: 45689
A12: SKU-006 | B12: Dress Casual Wanita | C12: Fashion | D12: -28 | E12: 45 | F12: 7 | G12: 5 | H12: SUP_FA01 | I12: 45664 | J12: 450000 | K12: 45658
A13: SKU-011 | B13: Vacuum Cleaner Deerma | C13: Home & Living | D13: -18 | E13: 15 | F13: 4 | G13: 6 | H13: SUP_HM02 | I13: 46099 | J13: 1200000 | K13: 46082
... A76: SKU-002 | B76: Smartphone Samsung A54 | C76: Electronics | D76: 42 | E76: 25 | F76: 4 | G76: 19 | H76: SUP_EL02 | I76: 45881 | J76: 4500000 | K76: 45870
A77: SKU-019 | B77: Madu Hutan Asli 500ml | C77: Food & Beverage | D77: 18 | E77: 60 | F77: 8 | G77: 5 | H77: SUP_FB02 | I77: 45712 | K77: 45689
A78: SKU-004 | B78: Smartwatch Xiaomi Band | C78: Electronics | D78: 17 | E78: 30 | F78: 6 | G78: 8 | H78: SUP_EL01 | I78: 45996 | J78: 1200000 | K78: 45992
A79: SKU-016 | B79: Parfum EDT Brasov 100ml | C79: Beauty | D79: 238 | E79: 50 | F79: 2 | G79: 7 | H79: SUP_BT02 | I79: 45671 | J79: 125000 | K79: 45658
A80: SKU-008 | B80: Tas Ransel Eiger | C80: Fashion | D80: 0 | E80: 40 | F80: 10 | G80: 7 | H80: SUP_FA02 | I80: 46109 | J80: 550000 | K80: 46082
A81: SKU-018 | B81: Teh Organik Premium Box | C81: Food & Beverage | E81: 80 | F81: 11 | G81: 4 | H81: SUP_FB01 | I81: 45766 | J81: 65000 | K81: 45748
A82: SKU-017 | B82: Kopi Arabika 250g Pack | C82: Food & Beverage | D82: 26 | E82: 100 | F82: 16 | G82: 4 | H82: SUP_FB01 | I82: 45778 | J82: 85000 | K82: 45778
A83: SKU-014 | B83: Lipstik Matte Wardah | C83: Beauty | D83: 301 | E83: 80 | F83: 3 | G83: 4 | H83: SUP_BT01 | I83: 45936 | J83: 85000 | K83: 45931
A84: SKU-010 | B84: Rice Cooker Miyako 1.8L | C84: Home & Living | D84: 19 | E84: 25 | F84: 4 | G84: 10 | H84: SUP_HM01 | I84: 45729 | J84: 450000 | K84: 45717
A85: SKU-012 | B85: Kipas Angin Cosmos 16in | C85: Home & Living | D85: 51 | E85: 30 | F85: 6 | G85: 9 | H85: SUP_HM02 | I85: 45752 | J85: 350000 | K85: 45748
A86: SKU-007 | B86: Sepatu Sneakers Nike | C86: Fashion | D86: 17 | E86: 35 | F86: 5 | G86: 5 | H86: SUP_FA02 | I86: 45663 | J86: 1250000 | K86: 45658
A87: SKU-015 | B87: Foundation Maybelline Fit | C87: Beauty | D87: 223 | E87: 60 | F87: 4 | G87: 8 | H87: SUP_BT02 | I87: 46108 | J87: 165000 | K87: 46082
A88: SKU-005 | B88: Kemeja Formal Pria | C88: Fashion | D88: 34 | E88: 50 | F88: 6 | G88: 6 | H88: SUP_FA01 | I88: 45849 | J88: 350000 | K88: 45839
A89: SKU-008 | B89: Tas Ransel Eiger | C89: Fashion | D89: 10 | E89: 40 | F89: 4 | G89: 3 | H89: SUP_FA02 | I89: 46055 | J89: 550000 | K89: 46054
A90: SKU-014 | B90: Lipstik Matte Wardah | C90: Beauty | D90: 436 | E90: 80 | F90: 4 | G90: 4 | H90: SUP_BT01 | I90: 45755 | J90: 85000 | K90: 45748
A91: SKU-002 | B91: Smartphone Samsung A54 | C91: Electronics | D91: 0 | E91: 25 | F91: 8 | G91: 10 | H91: SUP_EL02 | I91: 46013 | J91: 4500000 | K91: 45992
A92: SKU-002 | B92: Smartphone Samsung A54 | C92: Electronics | D92: 20 | E92: 25 | F92: 4 | G92: 19 | H92: SUP_EL02 | I92: 45786 | J92: 4500000 | K92: 45778
A93: SKU-010 | B93: Rice Cooker Miyako 1.8L | C93: Home & Living | D93: 42 | E93: 25 | F93: 4 | G93: 8 | H93: SUP_HM01 | I93: 46029 | J93: 450000 | K93: 46023
... A122: SKU-007 | B122: Sepatu Sneakers Nike | C122: Fashion | D122: 18 | E122: 35 | F122: 7 | G122: 5 | H122: SUP_FA02 | I122: 45859 | J122: 1250000 | K122: 45839
A123: SKU-010 | B123: Rice Cooker Miyako 1.8L | C123: Home & Living | D123: 14 | E123: 25 | F123: 5 | G123: 9 | H123: SUP_HM01 | I123: 45816 | K123: 45809
A124: SKU-012 | B124: Kipas Angin Cosmos 16in | C124: Home & Living | D124: 34 | E124: 30 | F124: 5 | G124: 5 | H124: SUP_HM02 | I124: 46007 | J124: 350000 | K124: 45992
A125: SKU-006 | B125: Dress Casual Wanita | C125: Fashion | D125: 0 | E125: 45 | F125: 13 | G125: 7 | H125: SUP_FA01 | I125: 46015 | J125: 450000 | K125: 45992
A126: SKU-018 | B126: Teh Organik Premium Box | C126: Food & Beverage | D126: 17 | E126: 80 | F126: 11 | G126: 5 | H126: SUP_FB01 | I126: 45882 | J126: 65000 | K126: 45870
A127: SKU-019 | B127: Madu Hutan Asli 500ml | C127: Food & Beverage | D127: 0 | E127: 60 | F127: 14 | G127: 4 | H127: SUP_FB02 | I127: 45741 | J127: 175000 | K127: 45717
A128: SKU-011 | B128: Vacuum Cleaner Deerma | C128: Home & Living | D128: 13 | E128: 15 | F128: 2 | G128: 7 | H128: SUP_HM02 | I128: 45799 | J128: 1200000 | K128: 45778
A129: SKU-018 | B129: Teh Organik Premium Box | C129: Food & Beverage | D129: 9 | E129: 80 | F129: 11 | G129: 4 | H129: SUP_FB01 | I129: 46077 | J129: 65000 | K129: 46054
A130: SKU-015 | B130: Foundation Maybelline Fit | C130: Beauty | D130: 202 | E130: 60 | F130: 2 | G130: 4 | H130: SUP_BT02 | I130: 46019 | J130: 165000 | K130: 45992
...

Sheet Sheet4
A1: SKU | B1: ProductName | C1: Category | D1: CurrentStock | E1: ReorderPoint | F1: DailySalesAvg | G1: LeadTime | H1: SupplierID | I1: LastRestockDate | J1: UnitPrice | K1: SnapshotDate
A2: SKU-016 | B2: Parfum EDT Brasov 100ml | C2: Beauty | D2: 271 | E2: 50 | F2: 2 | G2: 4 | H2: SUP_BT02 | I2: 45748 | J2: 125000 | K2: 45748
A3: SKU-001 | B3: Laptop ASUS Vivobook | C3: Electronics | D3: 21 | E3: 15 | F3: 4 | G3: 5 | H3: SUP_EL01 | I3: 45942 | J3: 8500000 | K3: 45931
A4: SKU-004 | B4: Smartwatch Xiaomi Band | C4: Electronics | D4: 30 | E4: 30 | F4: 2 | G4: 7 | H4: SUP_EL01 | I4: 46029 | J4: 1200000 | K4: 46023
A5: SKU-005 | B5: Kemeja Formal Pria | C5: Fashion | D5: 25 | E5: 50 | F5: 6 | G5: 3 | H5: SUP_FA01 | I5: 45688 | J5: 350000 | K5: 45658
A6: SKU-002 | B6: Smartphone Samsung A54 | C6: Electronics | D6: 0 | E6: 25 | F6: 7 | G6: 21 | H6: SUP_EL02 | I6: 45978 | J6: 4500000 | K6: 45962
A7: SKU-005 | B7: Kemeja Formal Pria | C7: Fashion | D7: 0 | E7: 50 | F7: 11 | G7: 7 | H7: SUP_FA01 | I7: 45749 | J7: 350000 | K7: 45748
A8: SKU-007 | B8: Sepatu Sneakers Nike | C8: Fashion | D8: 0 | E8: 35 | F8: 8 | G8: 5 | H8: SUP_FA02 | I8: 45774 | J8: 1250000 | K8: 45748
A9: SKU-013 | B9: Skincare Set Whitelab | C9: Beauty | D9: 220 | E9: 40 | F9: 2 | G9: 5 | H9: SUP_BT01 | I9: 45831 | J9: 550000 | K9: 45809
A10: SKU-018 | B10: Teh Organik Premium Box | C10: Food & Beverage | D10: 28 | E10: 80 | F10: 11 | G10: 4 | H10: SUP_FB01 | I10: 45812 | J10: 65000 | K10: 45809
A11: SKU-004 | B11: Smartwatch Xiaomi Band | C11: Electronics | D11: 24 | E11: 30 | F11: 3 | G11: 6 | H11: SUP_EL01 | I11: 45695 | J11: 1200000 | K11: 45689
A12: SKU-012 | B12: Kipas Angin Cosmos 16in | C12: Home & Living | D12: 54 | E12: 30 | F12: 6 | G12: 8 | H12: SUP_HM02 | I12: 45983 | J12: 350000 | K12: 45962
A13: SKU-008 | B13: Tas Ransel Eiger | C13: Fashion | D13: 0 | E13: 40 | F13: 7 | G13: 4 | H13: SUP_FA02 | I13: 45761 | J13: 550000 | K13: 45748
... A72: SKU-002 | B72: Smartphone Samsung A54 | C72: Electronics | D72: 42 | E72: 25 | F72: 4 | G72: 19 | H72: SUP_EL02 | I72: 45881 | J72: 4500000 | K72: 45870
A73: SKU-019 | B73: Madu Hutan Asli 500ml | C73: Food & Beverage | D73: 18 | E73: 60 | F73: 8 | G73: 5 | H73: SUP_FB02 | I73: 45712 | K73: 45689
A74: SKU-004 | B74: Smartwatch Xiaomi Band | C74: Electronics | D74: 17 | E74: 30 | F74: 6 | G74: 8 | H74: SUP_EL01 | I74: 45996 | J74: 1200000 | K74: 45992
A75: SKU-016 | B75: Parfum EDT Brasov 100ml | C75: Beauty | D75: 238 | E75: 50 | F75: 2 | G75: 7 | H75: SUP_BT02 | I75: 45671 | J75: 125000 | K75: 45658
A76: SKU-008 | B76: Tas Ransel Eiger | C76: Fashion | D76: 0 | E76: 40 | F76: 10 | G76: 7 | H76: SUP_FA02 | I76: 46109 | J76: 550000 | K76: 46082
A77: SKU-017 | B77: Kopi Arabika 250g Pack | C77: Food & Beverage | D77: 26 | E77: 100 | F77: 16 | G77: 4 | H77: SUP_FB01 | I77: 45778 | J77: 85000 | K77: 45778
A78: SKU-014 | B78: Lipstik Matte Wardah | C78: Beauty | D78: 301 | E78: 80 | F78: 3 | G78: 4 | H78: SUP_BT01 | I78: 45936 | J78: 85000 | K78: 45931
A79: SKU-010 | B79: Rice Cooker Miyako 1.8L | C79: Home & Living | D79: 19 | E79: 25 | F79: 4 | G79: 10 | H79: SUP_HM01 | I79: 45729 | J79: 450000 | K79: 45717
A80: SKU-012 | B80: Kipas Angin Cosmos 16in | C80: Home & Living | D80: 51 | E80: 30 | F80: 6 | G80: 9 | H80: SUP_HM02 | I80: 45752 | J80: 350000 | K80: 45748
A81: SKU-007 | B81: Sepatu Sneakers Nike | C81: Fashion | D81: 17 | E81: 35 | F81: 5 | G81: 5 | H81: SUP_FA02 | I81: 45663 | J81: 1250000 | K81: 45658
A82: SKU-015 | B82: Foundation Maybelline Fit | C82: Beauty | D82: 223 | E82: 60 | F82: 4 | G82: 8 | H82: SUP_BT02 | I82: 46108 | J82: 165000 | K82: 46082
A83: SKU-005 | B83: Kemeja Formal Pria | C83: Fashion | D83: 34 | E83: 50 | F83: 6 | G83: 6 | H83: SUP_FA01 | I83: 45849 | J83: 350000 | K83: 45839
A84: SKU-008 | B84: Tas Ransel Eiger | C84: Fashion | D84: 10 | E84: 40 | F84: 4 | G84: 3 | H84: SUP_FA02 | I84: 46055 | J84: 550000 | K84: 46054
A85: SKU-014 | B85: Lipstik Matte Wardah | C85: Beauty | D85: 436 | E85: 80 | F85: 4 | G85: 4 | H85: SUP_BT01 | I85: 45755 | J85: 85000 | K85: 45748
... A115: SKU-007 | B115: Sepatu Sneakers Nike | C115: Fashion | D115: 18 | E115: 35 | F115: 7 | G115: 5 | H115: SUP_FA02 | I115: 45859 | J115: 1250000 | K115: 45839
A116: SKU-010 | B116: Rice Cooker Miyako 1.8L | C116: Home & Living | D116: 14 | E116: 25 | F116: 5 | G116: 9 | H116: SUP_HM01 | I116: 45816 | K116: 45809
A117: SKU-012 | B117: Kipas Angin Cosmos 16in | C117: Home & Living | D117: 34 | E117: 30 | F117: 5 | G117: 5 | H117: SUP_HM02 | I117: 46007 | J117: 350000 | K117: 45992
A118: SKU-006 | B118: Dress Casual Wanita | C118: Fashion | D118: 0 | E118: 45 | F118: 13 | G118: 7 | H118: SUP_FA01 | I118: 46015 | J118: 450000 | K118: 45992
A119: SKU-018 | B119: Teh Organik Premium Box | C119: Food & Beverage | D119: 17 | E119: 80 | F119: 11 | G119: 5 | H119: SUP_FB01 | I119: 45882 | J119: 65000 | K119: 45870
A120: SKU-019 | B120: Madu Hutan Asli 500ml | C120: Food & Beverage | D120: 0 | E120: 60 | F120: 14 | G120: 4 | H120: SUP_FB02 | I120: 45741 | J120: 175000 | K120: 45717
A121: SKU-011 | B121: Vacuum Cleaner Deerma | C121: Home & Living | D121: 13 | E121: 15 | F121: 2 | G121: 7 | H121: SUP_HM02 | I121: 45799 | J121: 1200000 | K121: 45778
A122: SKU-018 | B122: Teh Organik Premium Box | C122: Food & Beverage | D122: 9 | E122: 80 | F122: 11 | G122: 4 | H122: SUP_FB01 | I122: 46077 | J122: 65000 | K122: 46054
A123: SKU-015 | B123: Foundation Maybelline Fit | C123: Beauty | D123: 202 | E123: 60 | F123: 2 | G123: 4 | H123: SUP_BT02 | I123: 46019 | J123: 165000 | K123: 45992
A124: SKU-015 | B124: Foundation Maybelline Fit | C124: Beauty | D124: 252 | E124: 60 | F124: 4 | G124: 7 | H124: SUP_BT02 | I124: 45930 | J124: 165000 | K124: 45901
A125: SKU-009 | B125: Blender Philips HR2157 | C125: Home & Living | D125: 20 | E125: 20 | F125: 2 | G125: 7 | H125: SUP_HM01 | I125: 46027 | J125: 750000 | K125: 46023
A126: SKU-013 | B126: Skincare Set Whitelab | C126: Beauty | D126: 153 | E126: 40 | F126: 4 | G126: 5 | H126: SUP_BT01 | I126: 46097 | J126: 550000 | K126: 46082
A127: SKU-010 | B127: Rice Cooker Miyako 1.8L | C127: Home & Living | D127: 41 | E127: 25 | F127: 4 | G127: 10 | H127: SUP_HM01 | I127: 45801 | J127: 450000 | K127: 45778
...

Sheet Data Clean
A1: SKU | B1: ProductName | C1: Category | D1: CurrentStock | E1: ReorderPoint | F1: DailySalesAvg | G1: LeadTime | H1: SupplierID | I1: LastRestockDate | J1: UnitPrice | K1: SnapshotDate | L1: Stockout
A2: SKU-001 | B2: Laptop ASUS Vivobook | C2: Electronics | D2: 17 | E2: 15 | F2: 1 | G2: 6 | H2: SUP_EL01 | I2: 45665 | J2: 8500000 | K2: 45658 | L2: =IF(D2 <= E2, "STOCKOUT", "OK") -> OK | N2: =COUNTIF(L:L, "STOCKOUT") -> 152
A3: SKU-001 | B3: Laptop ASUS Vivobook | C3: Electronics | D3: 13 | E3: 15 | F3: 1 | G3: 5 | H3: SUP_EL01 | I3: 45710 | J3: 8500000 | K3: 45689 | L3: =IF(D3 <= E3, "STOCKOUT", "OK") -> STOCKOUT
A4: SKU-001 | B4: Laptop ASUS Vivobook | C4: Electronics | D4: 25 | E4: 15 | F4: 2 | G4: 8 | H4: SUP_EL01 | I4: 45718 | J4: 8500000 | K4: 45717 | L4: =IF(D4 <= E4, "STOCKOUT", "OK") -> OK
A5: SKU-001 | B5: Laptop ASUS Vivobook | C5: Electronics | D5: 11 | E5: 15 | F5: 1 | G5: 5 | H5: SUP_EL01 | I5: 45754 | J5: 8500000 | K5: 45748 | L5: =IF(D5 <= E5, "STOCKOUT", "OK") -> STOCKOUT
A6: SKU-001 | B6: Laptop ASUS Vivobook | C6: Electronics | D6: 28 | E6: 15 | F6: 1 | G6: 6 | H6: SUP_EL01 | I6: 45800 | J6: 8500000 | K6: 45778 | L6: =IF(D6 <= E6, "STOCKOUT", "OK") -> OK
A7: SKU-001 | B7: Laptop ASUS Vivobook | C7: Electronics | D7: 26 | E7: 15 | F7: 3 | G7: 8 | H7: SUP_EL01 | I7: 45816 | J7: 8500000 | K7: 45809 | L7: =IF(D7 <= E7, "STOCKOUT", "OK") -> OK
A8: SKU-001 | B8: Laptop ASUS Vivobook | C8: Electronics | D8: 1 | E8: 15 | F8: 2 | G8: 6 | H8: SUP_EL01 | I8: 45861 | J8: 8500000 | K8: 45839 | L8: =IF(D8 <= E8, "STOCKOUT", "OK") -> STOCKOUT
A9: SKU-001 | B9: Laptop ASUS Vivobook | C9: Electronics | D9: 22 | E9: 15 | F9: 2 | G9: 7 | H9: SUP_EL01 | I9: 45878 | J9: 8500000 | K9: 45870 | L9: =IF(D9 <= E9, "STOCKOUT", "OK") -> OK
A10: SKU-001 | B10: Laptop ASUS Vivobook | C10: Electronics | D10: 19 | E10: 15 | F10: 3 | G10: 5 | H10: SUP_EL01 | I10: 45903 | J10: 8500000 | K10: 45901 | L10: =IF(D10 <= E10, "STOCKOUT", "OK") -> OK
A11: SKU-001 | B11: Laptop ASUS Vivobook | C11: Electronics | D11: 21 | E11: 15 | F11: 4 | G11: 5 | H11: SUP_EL01 | I11: 45942 | J11: 8500000 | K11: 45931 | L11: =IF(D11 <= E11, "STOCKOUT", "OK") -> OK
A12: SKU-001 | B12: Laptop ASUS Vivobook | C12: Electronics | D12: 0 | E12: 15 | F12: 3 | G12: 8 | H12: SUP_EL01 | I12: 45979 | J12: 8500000 | K12: 45962 | L12: =IF(D12 <= E12, "STOCKOUT", "OK") -> STOCKOUT
A13: SKU-001 | B13: Laptop ASUS Vivobook | C13: Electronics | D13: 0 | E13: 15 | F13: 2 | G13: 8 | H13: SUP_EL01 | I13: 45994 | J13: 8500000 | K13: 45992 | L13: =IF(D13 <= E13, "STOCKOUT", "OK") -> STOCKOUT
A14: SKU-001 | B14: Laptop ASUS Vivobook | C14: Electronics | D14: 28 | E14: 15 | F14: 1 | G14: 7 | H14: SUP_EL01 | I14: 46041 | J14: 8500000 | K14: 46023 | L14: =IF(D14 <= E14, "STOCKOUT", "OK") -> OK
... A283: SKU-020 | B283: Snack Granola Mix 500g | C283: Food & Beverage | D283: 48 | E283: 120 | F283: 18 | G283: 6 | H283: SUP_FB02 | I283: 46074 | J283: 55000 | K283: 46054 | L283: =IF(D283 <= E283, "STOCKOUT", "OK") -> STOCKOUT

Sheet 8 Negative Values (Live)
A1: SKU | B1: ProductName | C1: Category | D1: CurrentStock | E1: ReorderPoint | F1: DailySalesAvg | G1: LeadTime | H1: SupplierID | I1: LastRestockDate | J1: UnitPrice | K1: SnapshotDate
A2: SKU-016 | B2: Parfum EDT Brasov 100ml | C2: Beauty | D2: 271 | E2: 50 | F2: 2 | G2: 4 | H2: SUP_BT02 | I2: 45748 | J2: 125000 | K2: 45748
A3: SKU-001 | B3: Laptop ASUS Vivobook | C3: Electronics | D3: 21 | E3: 15 | F3: 4 | G3: 5 | H3: SUP_EL01 | I3: 45942 | J3: 8500000 | K3: 45931
A4: SKU-004 | B4: Smartwatch Xiaomi Band | C4: Electronics | D4: 30 | E4: 30 | F4: 2 | G4: 7 | H4: SUP_EL01 | I4: 46029 | J4: 1200000 | K4: 46023
A5: SKU-005 | B5: Kemeja Formal Pria | C5: Fashion | D5: 25 | E5: 50 | F5: 6 | G5: 3 | H5: SUP_FA01 | I5: 45688 | J5: 350000 | K5: 45658
A6: SKU-002 | B6: Smartphone Samsung A54 | C6: Electronics | D6: 0 | E6: 25 | F6: 7 | G6: 21 | H6: SUP_EL02 | I6: 45978 | J6: 4500000 | K6: 45962
A7: SKU-005 | B7: Kemeja Formal Pria | C7: Fashion | D7: 0 | E7: 50 | F7: 11 | G7: 7 | H7: SUP_FA01 | I7: 45749 | J7: 350000 | K7: 45748
A8: SKU-007 | B8: Sepatu Sneakers Nike | C8: Fashion | D8: 0 | E8: 35 | F8: 8 | G8: 5 | H8: SUP_FA02 | I8: 45774 | J8: 1250000 | K8: 45748
A9: SKU-013 | B9: Skincare Set Whitelab | C9: Beauty | D9: 220 | E9: 40 | F9: 2 | G9: 5 | H9: SUP_BT01 | I9: 45831 | J9: 550000 | K9: 45809
A10: SKU-018 | B10: Teh Organik Premium Box | C10: Food & Beverage | D10: 28 | E10: 80 | F10: 11 | G10: 4 | H10: SUP_FB01 | I10: 45812 | J10: 65000 | K10: 45809
A11: SKU-004 | B11: Smartwatch Xiaomi Band | C11: Electronics | D11: 24 | E11: 30 | F11: 3 | G11: 6 | H11: SUP_EL01 | I11: 45695 | J11: 1200000 | K11: 45689
A12: SKU-006 | B12: Dress Casual Wanita | C12: Fashion | D12: -28 | E12: 45 | F12: 7 | G12: 5 | H12: SUP_FA01 | I12: 45664 | J12: 450000 | K12: 45658
A13: SKU-011 | B13: Vacuum Cleaner Deerma | C13: Home & Living | D13: -18 | E13: 15 | F13: 4 | G13: 6 | H13: SUP_HM02 | I13: 46099 | J13: 1200000 | K13: 46082
... A76: SKU-002 | B76: Smartphone Samsung A54 | C76: Electronics | D76: 42 | E76: 25 | F76: 4 | G76: 19 | H76: SUP_EL02 | I76: 45881 | J76: 4500000 | K76: 45870
A77: SKU-019 | B77: Madu Hutan Asli 500ml | C77: Food & Beverage | D77: 18 | E77: 60 | F77: 8 | G77: 5 | H77: SUP_FB02 | I77: 45712 | K77: 45689
A78: SKU-004 | B78: Smartwatch Xiaomi Band | C78: Electronics | D78: 17 | E78: 30 | F78: 6 | G78: 8 | H78: SUP_EL01 | I78: 45996 | J78: 1200000 | K78: 45992
A79: SKU-016 | B79: Parfum EDT Brasov 100ml | C79: Beauty | D79: 238 | E79: 50 | F79: 2 | G79: 7 | H79: SUP_BT02 | I79: 45671 | J79: 125000 | K79: 45658
A80: SKU-008 | B80: Tas Ransel Eiger | C80: Fashion | D80: 0 | E80: 40 | F80: 10 | G80: 7 | H80: SUP_FA02 | I80: 46109 | J80: 550000 | K80: 46082
A81: SKU-018 | B81: Teh Organik Premium Box | C81: Food & Beverage | E81: 80 | F81: 11 | G81: 4 | H81: SUP_FB01 | I81: 45766 | J81: 65000 | K81: 45748
A82: SKU-017 | B82: Kopi Arabika 250g Pack | C82: Food & Beverage | D82: 26 | E82: 100 | F82: 16 | G82: 4 | H82: SUP_FB01 | I82: 45778 | J82: 85000 | K82: 45778
A83: SKU-014 | B83: Lipstik Matte Wardah | C83: Beauty | D83: 301 | E83: 80 | F83: 3 | G83: 4 | H83: SUP_BT01 | I83: 45936 | J83: 85000 | K83: 45931
A84: SKU-010 | B84: Rice Cooker Miyako 1.8L | C84: Home & Living | D84: 19 | E84: 25 | F84: 4 | G84: 10 | H84: SUP_HM01 | I84: 45729 | J84: 450000 | K84: 45717
A85: SKU-012 | B85: Kipas Angin Cosmos 16in | C85: Home & Living | D85: 51 | E85: 30 | F85: 6 | G85: 9 | H85: SUP_HM02 | I85: 45752 | J85: 350000 | K85: 45748
A86: SKU-007 | B86: Sepatu Sneakers Nike | C86: Fashion | D86: 17 | E86: 35 | F86: 5 | G86: 5 | H86: SUP_FA02 | I86: 45663 | J86: 1250000 | K86: 45658
A87: SKU-015 | B87: Foundation Maybelline Fit | C87: Beauty | D87: 223 | E87: 60 | F87: 4 | G87: 8 | H87: SUP_BT02 | I87: 46108 | J87: 165000 | K87: 46082
A88: SKU-005 | B88: Kemeja Formal Pria | C88: Fashion | D88: 34 | E88: 50 | F88: 6 | G88: 6 | H88: SUP_FA01 | I88: 45849 | J88: 350000 | K88: 45839
A89: SKU-008 | B89: Tas Ransel Eiger | C89: Fashion | D89: 10 | E89: 40 | F89: 4 | G89: 3 | H89: SUP_FA02 | I89: 46055 | J89: 550000 | K89: 46054
A90: SKU-014 | B90: Lipstik Matte Wardah | C90: Beauty | D90: 436 | E90: 80 | F90: 4 | G90: 4 | H90: SUP_BT01 | I90: 45755 | J90: 85000 | K90: 45748
A91: SKU-002 | B91: Smartphone Samsung A54 | C91: Electronics | D91: 0 | E91: 25 | F91: 8 | G91: 10 | H91: SUP_EL02 | I91: 46013 | J91: 4500000 | K91: 45992
A92: SKU-002 | B92: Smartphone Samsung A54 | C92: Electronics | D92: 20 | E92: 25 | F92: 4 | G92: 19 | H92: SUP_EL02 | I92: 45786 | J92: 4500000 | K92: 45778
A93: SKU-010 | B93: Rice Cooker Miyako 1.8L | C93: Home & Living | D93: 42 | E93: 25 | F93: 4 | G93: 8 | H93: SUP_HM01 | I93: 46029 | J93: 450000 | K93: 46023
... A122: SKU-007 | B122: Sepatu Sneakers Nike | C122: Fashion | D122: 18 | E122: 35 | F122: 7 | G122: 5 | H122: SUP_FA02 | I122: 45859 | J122: 1250000 | K122: 45839
A123: SKU-010 | B123: Rice Cooker Miyako 1.8L | C123: Home & Living | D123: 14 | E123: 25 | F123: 5 | G123: 9 | H123: SUP_HM01 | I123: 45816 | K123: 45809
A124: SKU-012 | B124: Kipas Angin Cosmos 16in | C124: Home & Living | D124: 34 | E124: 30 | F124: 5 | G124: 5 | H124: SUP_HM02 | I124: 46007 | J124: 350000 | K124: 45992
A125: SKU-006 | B125: Dress Casual Wanita | C125: Fashion | D125: 0 | E125: 45 | F125: 13 | G125: 7 | H125: SUP_FA01 | I125: 46015 | J125: 450000 | K125: 45992
A126: SKU-018 | B126: Teh Organik Premium Box | C126: Food & Beverage | D126: 17 | E126: 80 | F126: 11 | G126: 5 | H126: SUP_FB01 | I126: 45882 | J126: 65000 | K126: 45870
A127: SKU-019 | B127: Madu Hutan Asli 500ml | C127: Food & Beverage | D127: 0 | E127: 60 | F127: 14 | G127: 4 | H127: SUP_FB02 | I127: 45741 | J127: 175000 | K127: 45717
A128: SKU-011 | B128: Vacuum Cleaner Deerma | C128: Home & Living | D128: 13 | E128: 15 | F128: 2 | G128: 7 | H128: SUP_HM02 | I128: 45799 | J128: 1200000 | K128: 45778
A129: SKU-018 | B129: Teh Organik Premium Box | C129: Food & Beverage | D129: 9 | E129: 80 | F129: 11 | G129: 4 | H129: SUP_FB01 | I129: 46077 | J129: 65000 | K129: 46054
A130: SKU-015 | B130: Foundation Maybelline Fit | C130: Beauty | D130: 202 | E130: 60 | F130: 2 | G130: 4 | H130: SUP_BT02 | I130: 46019 | J130: 165000 | K130: 45992
...

Sheet 8 Negative Values
A1: SKU | B1: ProductName | C1: Category | D1: CurrentStock | E1: ReorderPoint | F1: DailySalesAvg | G1: LeadTime | H1: SupplierID | I1: LastRestockDate | J1: UnitPrice | K1: SnapshotDate
A2: SKU-016 | B2: Parfum EDT Brasov 100ml | C2: Beauty | D2: 271 | E2: 50 | F2: 2 | G2: 4 | H2: SUP_BT02 | I2: 45748 | J2: 125000 | K2: 45748
A3: SKU-001 | B3: Laptop ASUS Vivobook | C3: Electronics | D3: 21 | E3: 15 | F3: 4 | G3: 5 | H3: SUP_EL01 | I3: 45942 | J3: 8500000 | K3: 45931
A4: SKU-004 | B4: Smartwatch Xiaomi Band | C4: Electronics | D4: 30 | E4: 30 | F4: 2 | G4: 7 | H4: SUP_EL01 | I4: 46029 | J4: 1200000 | K4: 46023
A5: SKU-005 | B5: Kemeja Formal Pria | C5: Fashion | D5: 25 | E5: 50 | F5: 6 | G5: 3 | H5: SUP_FA01 | I5: 45688 | J5: 350000 | K5: 45658
A6: SKU-002 | B6: Smartphone Samsung A54 | C6: Electronics | D6: 0 | E6: 25 | F6: 7 | G6: 21 | H6: SUP_EL02 | I6: 45978 | J6: 4500000 | K6: 45962
A7: SKU-005 | B7: Kemeja Formal Pria | C7: Fashion | D7: 0 | E7: 50 | F7: 11 | G7: 7 | H7: SUP_FA01 | I7: 45749 | J7: 350000 | K7: 45748
A8: SKU-007 | B8: Sepatu Sneakers Nike | C8: Fashion | D8: 0 | E8: 35 | F8: 8 | G8: 5 | H8: SUP_FA02 | I8: 45774 | J8: 1250000 | K8: 45748
A9: SKU-013 | B9: Skincare Set Whitelab | C9: Beauty | D9: 220 | E9: 40 | F9: 2 | G9: 5 | H9: SUP_BT01 | I9: 45831 | J9: 550000 | K9: 45809
A10: SKU-018 | B10: Teh Organik Premium Box | C10: Food & Beverage | D10: 28 | E10: 80 | F10: 11 | G10: 4 | H10: SUP_FB01 | I10: 45812 | J10: 65000 | K10: 45809
A11: SKU-004 | B11: Smartwatch Xiaomi Band | C11: Electronics | D11: 24 | E11: 30 | F11: 3 | G11: 6 | H11: SUP_EL01 | I11: 45695 | J11: 1200000 | K11: 45689
A12: SKU-006 | B12: Dress Casual Wanita | C12: Fashion | D12: -28 | E12: 45 | F12: 7 | G12: 5 | H12: SUP_FA01 | I12: 45664 | J12: 450000 | K12: 45658
A13: SKU-011 | B13: Vacuum Cleaner Deerma | C13: Home & Living | D13: -18 | E13: 15 | F13: 4 | G13: 6 | H13: SUP_HM02 | I13: 46099 | J13: 1200000 | K13: 46082
... A76: SKU-002 | B76: Smartphone Samsung A54 | C76: Electronics | D76: 42 | E76: 25 | F76: 4 | G76: 19 | H76: SUP_EL02 | I76: 45881 | J76: 4500000 | K76: 45870
A77: SKU-019 | B77: Madu Hutan Asli 500ml | C77: Food & Beverage | D77: 18 | E77: 60 | F77: 8 | G77: 5 | H77: SUP_FB02 | I77: 45712 | K77: 45689
A78: SKU-004 | B78: Smartwatch Xiaomi Band | C78: Electronics | D78: 17 | E78: 30 | F78: 6 | G78: 8 | H78: SUP_EL01 | I78: 45996 | J78: 1200000 | K78: 45992
A79: SKU-016 | B79: Parfum EDT Brasov 100ml | C79: Beauty | D79: 238 | E79: 50 | F79: 2 | G79: 7 | H79: SUP_BT02 | I79: 45671 | J79: 125000 | K79: 45658
A80: SKU-008 | B80: Tas Ransel Eiger | C80: Fashion | D80: 0 | E80: 40 | F80: 10 | G80: 7 | H80: SUP_FA02 | I80: 46109 | J80: 550000 | K80: 46082
A81: SKU-018 | B81: Teh Organik Premium Box | C81: Food & Beverage | E81: 80 | F81: 11 | G81: 4 | H81: SUP_FB01 | I81: 45766 | J81: 65000 | K81: 45748
A82: SKU-017 | B82: Kopi Arabika 250g Pack | C82: Food & Beverage | D82: 26 | E82: 100 | F82: 16 | G82: 4 | H82: SUP_FB01 | I82: 45778 | J82: 85000 | K82: 45778
A83: SKU-014 | B83: Lipstik Matte Wardah | C83: Beauty | D83: 301 | E83: 80 | F83: 3 | G83: 4 | H83: SUP_BT01 | I83: 45936 | J83: 85000 | K83: 45931
A84: SKU-010 | B84: Rice Cooker Miyako 1.8L | C84: Home & Living | D84: 19 | E84: 25 | F84: 4 | G84: 10 | H84: SUP_HM01 | I84: 45729 | J84: 450000 | K84: 45717
A85: SKU-012 | B85: Kipas Angin Cosmos 16in | C85: Home & Living | D85: 51 | E85: 30 | F85: 6 | G85: 9 | H85: SUP_HM02 | I85: 45752 | J85: 350000 | K85: 45748
A86: SKU-007 | B86: Sepatu Sneakers Nike | C86: Fashion | D86: 17 | E86: 35 | F86: 5 | G86: 5 | H86: SUP_FA02 | I86: 45663 | J86: 1250000 | K86: 45658
A87: SKU-015 | B87: Foundation Maybelline Fit | C87: Beauty | D87: 223 | E87: 60 | F87: 4 | G87: 8 | H87: SUP_BT02 | I87: 46108 | J87: 165000 | K87: 46082
A88: SKU-005 | B88: Kemeja Formal Pria | C88: Fashion | D88: 34 | E88: 50 | F88: 6 | G88: 6 | H88: SUP_FA01 | I88: 45849 | J88: 350000 | K88: 45839
A89: SKU-008 | B89: Tas Ransel Eiger | C89: Fashion | D89: 10 | E89: 40 | F89: 4 | G89: 3 | H89: SUP_FA02 | I89: 46055 | J89: 550000 | K89: 46054
A90: SKU-014 | B90: Lipstik Matte Wardah | C90: Beauty | D90: 436 | E90: 80 | F90: 4 | G90: 4 | H90: SUP_BT01 | I90: 45755 | J90: 85000 | K90: 45748
A91: SKU-002 | B91: Smartphone Samsung A54 | C91: Electronics | D91: 0 | E91: 25 | F91: 8 | G91: 10 | H91: SUP_EL02 | I91: 46013 | J91: 4500000 | K91: 45992
A92: SKU-002 | B92: Smartphone Samsung A54 | C92: Electronics | D92: 20 | E92: 25 | F92: 4 | G92: 19 | H92: SUP_EL02 | I92: 45786 | J92: 4500000 | K92: 45778
A93: SKU-010 | B93: Rice Cooker Miyako 1.8L | C93: Home & Living | D93: 42 | E93: 25 | F93: 4 | G93: 8 | H93: SUP_HM01 | I93: 46029 | J93: 450000 | K93: 46023
... A122: SKU-007 | B122: Sepatu Sneakers Nike | C122: Fashion | D122: 18 | E122: 35 | F122: 7 | G122: 5 | H122: SUP_FA02 | I122: 45859 | J122: 1250000 | K122: 45839
A123: SKU-010 | B123: Rice Cooker Miyako 1.8L | C123: Home & Living | D123: 14 | E123: 25 | F123: 5 | G123: 9 | H123: SUP_HM01 | I123: 45816 | K123: 45809
A124: SKU-012 | B124: Kipas Angin Cosmos 16in | C124: Home & Living | D124: 34 | E124: 30 | F124: 5 | G124: 5 | H124: SUP_HM02 | I124: 46007 | J124: 350000 | K124: 45992
A125: SKU-006 | B125: Dress Casual Wanita | C125: Fashion | D125: 0 | E125: 45 | F125: 13 | G125: 7 | H125: SUP_FA01 | I125: 46015 | J125: 450000 | K125: 45992
A126: SKU-018 | B126: Teh Organik Premium Box | C126: Food & Beverage | D126: 17 | E126: 80 | F126: 11 | G126: 5 | H126: SUP_FB01 | I126: 45882 | J126: 65000 | K126: 45870
A127: SKU-019 | B127: Madu Hutan Asli 500ml | C127: Food & Beverage | D127: 0 | E127: 60 | F127: 14 | G127: 4 | H127: SUP_FB02 | I127: 45741 | J127: 175000 | K127: 45717
A128: SKU-011 | B128: Vacuum Cleaner Deerma | C128: Home & Living | D128: 13 | E128: 15 | F128: 2 | G128: 7 | H128: SUP_HM02 | I128: 45799 | J128: 1200000 | K128: 45778
A129: SKU-018 | B129: Teh Organik Premium Box | C129: Food & Beverage | D129: 9 | E129: 80 | F129: 11 | G129: 4 | H129: SUP_FB01 | I129: 46077 | J129: 65000 | K129: 46054
A130: SKU-015 | B130: Foundation Maybelline Fit | C130: Beauty | D130: 202 | E130: 60 | F130: 2 | G130: 4 | H130: SUP_BT02 | I130: 46019 | J130: 165000 | K130: 45992
...

Sheet 10 Missing Value (Live)
A1: SKU | B1: ProductName | C1: Category | D1: CurrentStock | E1: ReorderPoint | F1: DailySalesAvg | G1: LeadTime | H1: SupplierID | I1: LastRestockDate | J1: UnitPrice | K1: SnapshotDate
A2: SKU-016 | B2: Parfum EDT Brasov 100ml | C2: Beauty | D2: 271 | E2: 50 | F2: 2 | G2: 4 | H2: SUP_BT02 | I2: 45748 | J2: 125000 | K2: 45748 | L2: =COUNTBLANK($A2:$K2) > 0 -> FALSE
A3: SKU-001 | B3: Laptop ASUS Vivobook | C3: Electronics | D3: 21 | E3: 15 | F3: 4 | G3: 5 | H3: SUP_EL01 | I3: 45942 | J3: 8500000 | K3: 45931 | L3: =COUNTBLANK($A3:$K3) > 0 -> FALSE
A4: SKU-004 | B4: Smartwatch Xiaomi Band | C4: Electronics | D4: 30 | E4: 30 | F4: 2 | G4: 7 | H4: SUP_EL01 | I4: 46029 | J4: 1200000 | K4: 46023 | L4: =COUNTBLANK($A4:$K4) > 0 -> FALSE
A5: SKU-005 | B5: Kemeja Formal Pria | C5: Fashion | D5: 25 | E5: 50 | F5: 6 | G5: 3 | H5: SUP_FA01 | I5: 45688 | J5: 350000 | K5: 45658 | L5: =COUNTBLANK($A5:$K5) > 0 -> FALSE
A6: SKU-002 | B6: Smartphone Samsung A54 | C6: Electronics | D6: 0 | E6: 25 | F6: 7 | G6: 21 | H6: SUP_EL02 | I6: 45978 | J6: 4500000 | K6: 45962 | L6: =COUNTBLANK($A6:$K6) > 0 -> FALSE
A7: SKU-005 | B7: Kemeja Formal Pria | C7: Fashion | D7: 0 | E7: 50 | F7: 11 | G7: 7 | H7: SUP_FA01 | I7: 45749 | J7: 350000 | K7: 45748 | L7: =COUNTBLANK($A7:$K7) > 0 -> FALSE
A8: SKU-007 | B8: Sepatu Sneakers Nike | C8: Fashion | D8: 0 | E8: 35 | F8: 8 | G8: 5 | H8: SUP_FA02 | I8: 45774 | J8: 1250000 | K8: 45748 | L8: =COUNTBLANK($A8:$K8) > 0 -> FALSE
A9: SKU-013 | B9: Skincare Set Whitelab | C9: Beauty | D9: 220 | E9: 40 | F9: 2 | G9: 5 | H9: SUP_BT01 | I9: 45831 | J9: 550000 | K9: 45809 | L9: =COUNTBLANK($A9:$K9) > 0 -> FALSE
A10: SKU-018 | B10: Teh Organik Premium Box | C10: Food & Beverage | D10: 28 | E10: 80 | F10: 11 | G10: 4 | H10: SUP_FB01 | I10: 45812 | J10: 65000 | K10: 45809 | L10: =COUNTBLANK($A10:$K10) > 0 -> FALSE
A11: SKU-004 | B11: Smartwatch Xiaomi Band | C11: Electronics | D11: 24 | E11: 30 | F11: 3 | G11: 6 | H11: SUP_EL01 | I11: 45695 | J11: 1200000 | K11: 45689 | L11: =COUNTBLANK($A11:$K11) > 0 -> FALSE
A12: SKU-006 | B12: Dress Casual Wanita | C12: Fashion | D12: -28 | E12: 45 | F12: 7 | G12: 5 | H12: SUP_FA01 | I12: 45664 | J12: 450000 | K12: 45658 | L12: =COUNTBLANK($A12:$K12) > 0 -> FALSE
A13: SKU-011 | B13: Vacuum Cleaner Deerma | C13: Home & Living | D13: -18 | E13: 15 | F13: 4 | G13: 6 | H13: SUP_HM02 | I13: 46099 | J13: 1200000 | K13: 46082 | L13: =COUNTBLANK($A13:$K13) > 0 -> FALSE
... A76: SKU-002 | B76: Smartphone Samsung A54 | C76: Electronics | D76: 42 | E76: 25 | F76: 4 | G76: 19 | H76: SUP_EL02 | I76: 45881 | J76: 4500000 | K76: 45870 | L76: =COUNTBLANK($A76:$K76) > 0 -> FALSE
A77: SKU-019 | B77: Madu Hutan Asli 500ml | C77: Food & Beverage | D77: 18 | E77: 60 | F77: 8 | G77: 5 | H77: SUP_FB02 | I77: 45712 | K77: 45689 | L77: =COUNTBLANK($A77:$K77) > 0 -> TRUE
A78: SKU-004 | B78: Smartwatch Xiaomi Band | C78: Electronics | D78: 17 | E78: 30 | F78: 6 | G78: 8 | H78: SUP_EL01 | I78: 45996 | J78: 1200000 | K78: 45992 | L78: =COUNTBLANK($A78:$K78) > 0 -> FALSE
A79: SKU-016 | B79: Parfum EDT Brasov 100ml | C79: Beauty | D79: 238 | E79: 50 | F79: 2 | G79: 7 | H79: SUP_BT02 | I79: 45671 | J79: 125000 | K79: 45658 | L79: =COUNTBLANK($A79:$K79) > 0 -> FALSE
A80: SKU-008 | B80: Tas Ransel Eiger | C80: Fashion | D80: 0 | E80: 40 | F80: 10 | G80: 7 | H80: SUP_FA02 | I80: 46109 | J80: 550000 | K80: 46082 | L80: =COUNTBLANK($A80:$K80) > 0 -> FALSE
A81: SKU-018 | B81: Teh Organik Premium Box | C81: Food & Beverage | E81: 80 | F81: 11 | G81: 4 | H81: SUP_FB01 | I81: 45766 | J81: 65000 | K81: 45748 | L81: =COUNTBLANK($A81:$K81) > 0 -> TRUE
A82: SKU-017 | B82: Kopi Arabika 250g Pack | C82: Food & Beverage | D82: 26 | E82: 100 | F82: 16 | G82: 4 | H82: SUP_FB01 | I82: 45778 | J82: 85000 | K82: 45778 | L82: =COUNTBLANK($A82:$K82) > 0 -> FALSE
A83: SKU-014 | B83: Lipstik Matte Wardah | C83: Beauty | D83: 301 | E83: 80 | F83: 3 | G83: 4 | H83: SUP_BT01 | I83: 45936 | J83: 85000 | K83: 45931 | L83: =COUNTBLANK($A83:$K83) > 0 -> FALSE
A84: SKU-010 | B84: Rice Cooker Miyako 1.8L | C84: Home & Living | D84: 19 | E84: 25 | F84: 4 | G84: 10 | H84: SUP_HM01 | I84: 45729 | J84: 450000 | K84: 45717 | L84: =COUNTBLANK($A84:$K84) > 0 -> FALSE
A85: SKU-012 | B85: Kipas Angin Cosmos 16in | C85: Home & Living | D85: 51 | E85: 30 | F85: 6 | G85: 9 | H85: SUP_HM02 | I85: 45752 | J85: 350000 | K85: 45748 | L85: =COUNTBLANK($A85:$K85) > 0 -> FALSE
A86: SKU-007 | B86: Sepatu Sneakers Nike | C86: Fashion | D86: 17 | E86: 35 | F86: 5 | G86: 5 | H86: SUP_FA02 | I86: 45663 | J86: 1250000 | K86: 45658 | L86: =COUNTBLANK($A86:$K86) > 0 -> FALSE
A87: SKU-015 | B87: Foundation Maybelline Fit | C87: Beauty | D87: 223 | E87: 60 | F87: 4 | G87: 8 | H87: SUP_BT02 | I87: 46108 | J87: 165000 | K87: 46082 | L87: =COUNTBLANK($A87:$K87) > 0 -> FALSE
A88: SKU-005 | B88: Kemeja Formal Pria | C88: Fashion | D88: 34 | E88: 50 | F88: 6 | G88: 6 | H88: SUP_FA01 | I88: 45849 | J88: 350000 | K88: 45839 | L88: =COUNTBLANK($A88:$K88) > 0 -> FALSE
A89: SKU-008 | B89: Tas Ransel Eiger | C89: Fashion | D89: 10 | E89: 40 | F89: 4 | G89: 3 | H89: SUP_FA02 | I89: 46055 | J89: 550000 | K89: 46054 | L89: =COUNTBLANK($A89:$K89) > 0 -> FALSE
A90: SKU-014 | B90: Lipstik Matte Wardah | C90: Beauty | D90: 436 | E90: 80 | F90: 4 | G90: 4 | H90: SUP_BT01 | I90: 45755 | J90: 85000 | K90: 45748 | L90: =COUNTBLANK($A90:$K90) > 0 -> FALSE
A91: SKU-002 | B91: Smartphone Samsung A54 | C91: Electronics | D91: 0 | E91: 25 | F91: 8 | G91: 10 | H91: SUP_EL02 | I91: 46013 | J91: 4500000 | K91: 45992 | L91: =COUNTBLANK($A91:$K91) > 0 -> FALSE
A92: SKU-002 | B92: Smartphone Samsung A54 | C92: Electronics | D92: 20 | E92: 25 | F92: 4 | G92: 19 | H92: SUP_EL02 | I92: 45786 | J92: 4500000 | K92: 45778 | L92: =COUNTBLANK($A92:$K92) > 0 -> FALSE
A93: SKU-010 | B93: Rice Cooker Miyako 1.8L | C93: Home & Living | D93: 42 | E93: 25 | F93: 4 | G93: 8 | H93: SUP_HM01 | I93: 46029 | J93: 450000 | K93: 46023 | L93: =COUNTBLANK($A93:$K93) > 0 -> FALSE
... A122: SKU-007 | B122: Sepatu Sneakers Nike | C122: Fashion | D122: 18 | E122: 35 | F122: 7 | G122: 5 | H122: SUP_FA02 | I122: 45859 | J122: 1250000 | K122: 45839 | L122: =COUNTBLANK($A122:$K122) > 0 -> FALSE
A123: SKU-010 | B123: Rice Cooker Miyako 1.8L | C123: Home & Living | D123: 14 | E123: 25 | F123: 5 | G123: 9 | H123: SUP_HM01 | I123: 45816 | K123: 45809 | L123: =COUNTBLANK($A123:$K123) > 0 -> TRUE
A124: SKU-012 | B124: Kipas Angin Cosmos 16in | C124: Home & Living | D124: 34 | E124: 30 | F124: 5 | G124: 5 | H124: SUP_HM02 | I124: 46007 | J124: 350000 | K124: 45992 | L124: =COUNTBLANK($A124:$K124) > 0 -> FALSE
A125: SKU-006 | B125: Dress Casual Wanita | C125: Fashion | D125: 0 | E125: 45 | F125: 13 | G125: 7 | H125: SUP_FA01 | I125: 46015 | J125: 450000 | K125: 45992 | L125: =COUNTBLANK($A125:$K125) > 0 -> FALSE
A126: SKU-018 | B126: Teh Organik Premium Box | C126: Food & Beverage | D126: 17 | E126: 80 | F126: 11 | G126: 5 | H126: SUP_FB01 | I126: 45882 | J126: 65000 | K126: 45870 | L126: =COUNTBLANK($A126:$K126) > 0 -> FALSE
A127: SKU-019 | B127: Madu Hutan Asli 500ml | C127: Food & Beverage | D127: 0 | E127: 60 | F127: 14 | G127: 4 | H127: SUP_FB02 | I127: 45741 | J127: 175000 | K127: 45717 | L127: =COUNTBLANK($A127:$K127) > 0 -> FALSE
A128: SKU-011 | B128: Vacuum Cleaner Deerma | C128: Home & Living | D128: 13 | E128: 15 | F128: 2 | G128: 7 | H128: SUP_HM02 | I128: 45799 | J128: 1200000 | K128: 45778 | L128: =COUNTBLANK($A128:$K128) > 0 -> FALSE
A129: SKU-018 | B129: Teh Organik Premium Box | C129: Food & Beverage | D129: 9 | E129: 80 | F129: 11 | G129: 4 | H129: SUP_FB01 | I129: 46077 | J129: 65000 | K129: 46054 | L129: =COUNTBLANK($A129:$K129) > 0 -> FALSE
A130: SKU-015 | B130: Foundation Maybelline Fit | C130: Beauty | D130: 202 | E130: 60 | F130: 2 | G130: 4 | H130: SUP_BT02 | I130: 46019 | J130: 165000 | K130: 45992 | L130: =COUNTBLANK($A130:$K130) > 0 -> FALSE
...

Sheet 10 Missing Value
A1: SKU | B1: ProductName | C1: Category | D1: CurrentStock | E1: ReorderPoint | F1: DailySalesAvg | G1: LeadTime | H1: SupplierID | I1: LastRestockDate | J1: UnitPrice | K1: SnapshotDate
A2: SKU-016 | B2: Parfum EDT Brasov 100ml | C2: Beauty | D2: 271 | E2: 50 | F2: 2 | G2: 4 | H2: SUP_BT02 | I2: 45748 | J2: 125000 | K2: 45748
A3: SKU-001 | B3: Laptop ASUS Vivobook | C3: Electronics | D3: 21 | E3: 15 | F3: 4 | G3: 5 | H3: SUP_EL01 | I3: 45942 | J3: 8500000 | K3: 45931
A4: SKU-004 | B4: Smartwatch Xiaomi Band | C4: Electronics | D4: 30 | E4: 30 | F4: 2 | G4: 7 | H4: SUP_EL01 | I4: 46029 | J4: 1200000 | K4: 46023
A5: SKU-005 | B5: Kemeja Formal Pria | C5: Fashion | D5: 25 | E5: 50 | F5: 6 | G5: 3 | H5: SUP_FA01 | I5: 45688 | J5: 350000 | K5: 45658
A6: SKU-002 | B6: Smartphone Samsung A54 | C6: Electronics | D6: 0 | E6: 25 | F6: 7 | G6: 21 | H6: SUP_EL02 | I6: 45978 | J6: 4500000 | K6: 45962
A7: SKU-005 | B7: Kemeja Formal Pria | C7: Fashion | D7: 0 | E7: 50 | F7: 11 | G7: 7 | H7: SUP_FA01 | I7: 45749 | J7: 350000 | K7: 45748
A8: SKU-007 | B8: Sepatu Sneakers Nike | C8: Fashion | D8: 0 | E8: 35 | F8: 8 | G8: 5 | H8: SUP_FA02 | I8: 45774 | J8: 1250000 | K8: 45748
A9: SKU-013 | B9: Skincare Set Whitelab | C9: Beauty | D9: 220 | E9: 40 | F9: 2 | G9: 5 | H9: SUP_BT01 | I9: 45831 | J9: 550000 | K9: 45809
A10: SKU-018 | B10: Teh Organik Premium Box | C10: Food & Beverage | D10: 28 | E10: 80 | F10: 11 | G10: 4 | H10: SUP_FB01 | I10: 45812 | J10: 65000 | K10: 45809
A11: SKU-004 | B11: Smartwatch Xiaomi Band | C11: Electronics | D11: 24 | E11: 30 | F11: 3 | G11: 6 | H11: SUP_EL01 | I11: 45695 | J11: 1200000 | K11: 45689
A12: SKU-006 | B12: Dress Casual Wanita | C12: Fashion | D12: -28 | E12: 45 | F12: 7 | G12: 5 | H12: SUP_FA01 | I12: 45664 | J12: 450000 | K12: 45658
A13: SKU-011 | B13: Vacuum Cleaner Deerma | C13: Home & Living | D13: -18 | E13: 15 | F13: 4 | G13: 6 | H13: SUP_HM02 | I13: 46099 | J13: 1200000 | K13: 46082
... A76: SKU-002 | B76: Smartphone Samsung A54 | C76: Electronics | D76: 42 | E76: 25 | F76: 4 | G76: 19 | H76: SUP_EL02 | I76: 45881 | J76: 4500000 | K76: 45870
A77: SKU-019 | B77: Madu Hutan Asli 500ml | C77: Food & Beverage | D77: 18 | E77: 60 | F77: 8 | G77: 5 | H77: SUP_FB02 | I77: 45712 | K77: 45689
A78: SKU-004 | B78: Smartwatch Xiaomi Band | C78: Electronics | D78: 17 | E78: 30 | F78: 6 | G78: 8 | H78: SUP_EL01 | I78: 45996 | J78: 1200000 | K78: 45992
A79: SKU-016 | B79: Parfum EDT Brasov 100ml | C79: Beauty | D79: 238 | E79: 50 | F79: 2 | G79: 7 | H79: SUP_BT02 | I79: 45671 | J79: 125000 | K79: 45658
A80: SKU-008 | B80: Tas Ransel Eiger | C80: Fashion | D80: 0 | E80: 40 | F80: 10 | G80: 7 | H80: SUP_FA02 | I80: 46109 | J80: 550000 | K80: 46082
A81: SKU-018 | B81: Teh Organik Premium Box | C81: Food & Beverage | E81: 80 | F81: 11 | G81: 4 | H81: SUP_FB01 | I81: 45766 | J81: 65000 | K81: 45748
A82: SKU-017 | B82: Kopi Arabika 250g Pack | C82: Food & Beverage | D82: 26 | E82: 100 | F82: 16 | G82: 4 | H82: SUP_FB01 | I82: 45778 | J82: 85000 | K82: 45778
A83: SKU-014 | B83: Lipstik Matte Wardah | C83: Beauty | D83: 301 | E83: 80 | F83: 3 | G83: 4 | H83: SUP_BT01 | I83: 45936 | J83: 85000 | K83: 45931
A84: SKU-010 | B84: Rice Cooker Miyako 1.8L | C84: Home & Living | D84: 19 | E84: 25 | F84: 4 | G84: 10 | H84: SUP_HM01 | I84: 45729 | J84: 450000 | K84: 45717
A85: SKU-012 | B85: Kipas Angin Cosmos 16in | C85: Home & Living | D85: 51 | E85: 30 | F85: 6 | G85: 9 | H85: SUP_HM02 | I85: 45752 | J85: 350000 | K85: 45748
A86: SKU-007 | B86: Sepatu Sneakers Nike | C86: Fashion | D86: 17 | E86: 35 | F86: 5 | G86: 5 | H86: SUP_FA02 | I86: 45663 | J86: 1250000 | K86: 45658
A87: SKU-015 | B87: Foundation Maybelline Fit | C87: Beauty | D87: 223 | E87: 60 | F87: 4 | G87: 8 | H87: SUP_BT02 | I87: 46108 | J87: 165000 | K87: 46082
A88: SKU-005 | B88: Kemeja Formal Pria | C88: Fashion | D88: 34 | E88: 50 | F88: 6 | G88: 6 | H88: SUP_FA01 | I88: 45849 | J88: 350000 | K88: 45839
A89: SKU-008 | B89: Tas Ransel Eiger | C89: Fashion | D89: 10 | E89: 40 | F89: 4 | G89: 3 | H89: SUP_FA02 | I89: 46055 | J89: 550000 | K89: 46054
A90: SKU-014 | B90: Lipstik Matte Wardah | C90: Beauty | D90: 436 | E90: 80 | F90: 4 | G90: 4 | H90: SUP_BT01 | I90: 45755 | J90: 85000 | K90: 45748
A91: SKU-002 | B91: Smartphone Samsung A54 | C91: Electronics | D91: 0 | E91: 25 | F91: 8 | G91: 10 | H91: SUP_EL02 | I91: 46013 | J91: 4500000 | K91: 45992
A92: SKU-002 | B92: Smartphone Samsung A54 | C92: Electronics | D92: 20 | E92: 25 | F92: 4 | G92: 19 | H92: SUP_EL02 | I92: 45786 | J92: 4500000 | K92: 45778
A93: SKU-010 | B93: Rice Cooker Miyako 1.8L | C93: Home & Living | D93: 42 | E93: 25 | F93: 4 | G93: 8 | H93: SUP_HM01 | I93: 46029 | J93: 450000 | K93: 46023
... A122: SKU-007 | B122: Sepatu Sneakers Nike | C122: Fashion | D122: 18 | E122: 35 | F122: 7 | G122: 5 | H122: SUP_FA02 | I122: 45859 | J122: 1250000 | K122: 45839
A123: SKU-010 | B123: Rice Cooker Miyako 1.8L | C123: Home & Living | D123: 14 | E123: 25 | F123: 5 | G123: 9 | H123: SUP_HM01 | I123: 45816 | K123: 45809
A124: SKU-012 | B124: Kipas Angin Cosmos 16in | C124: Home & Living | D124: 34 | E124: 30 | F124: 5 | G124: 5 | H124: SUP_HM02 | I124: 46007 | J124: 350000 | K124: 45992
A125: SKU-006 | B125: Dress Casual Wanita | C125: Fashion | D125: 0 | E125: 45 | F125: 13 | G125: 7 | H125: SUP_FA01 | I125: 46015 | J125: 450000 | K125: 45992
A126: SKU-018 | B126: Teh Organik Premium Box | C126: Food & Beverage | D126: 17 | E126: 80 | F126: 11 | G126: 5 | H126: SUP_FB01 | I126: 45882 | J126: 65000 | K126: 45870
A127: SKU-019 | B127: Madu Hutan Asli 500ml | C127: Food & Beverage | D127: 0 | E127: 60 | F127: 14 | G127: 4 | H127: SUP_FB02 | I127: 45741 | J127: 175000 | K127: 45717
A128: SKU-011 | B128: Vacuum Cleaner Deerma | C128: Home & Living | D128: 13 | E128: 15 | F128: 2 | G128: 7 | H128: SUP_HM02 | I128: 45799 | J128: 1200000 | K128: 45778
A129: SKU-018 | B129: Teh Organik Premium Box | C129: Food & Beverage | D129: 9 | E129: 80 | F129: 11 | G129: 4 | H129: SUP_FB01 | I129: 46077 | J129: 65000 | K129: 46054
A130: SKU-015 | B130: Foundation Maybelline Fit | C130: Beauty | D130: 202 | E130: 60 | F130: 2 | G130: 4 | H130: SUP_BT02 | I130: 46019 | J130: 165000 | K130: 45992
...

Sheet 6 Future Dates (Live)
A1: SKU | B1: ProductName | C1: Category | D1: CurrentStock | E1: ReorderPoint | F1: DailySalesAvg | G1: LeadTime | H1: SupplierID | I1: LastRestockDate | J1: UnitPrice | K1: SnapshotDate
A2: SKU-016 | B2: Parfum EDT Brasov 100ml | C2: Beauty | D2: 271 | E2: 50 | F2: 2 | G2: 4 | H2: SUP_BT02 | I2: 45748 | J2: 125000 | K2: 45748
A3: SKU-001 | B3: Laptop ASUS Vivobook | C3: Electronics | D3: 21 | E3: 15 | F3: 4 | G3: 5 | H3: SUP_EL01 | I3: 45942 | J3: 8500000 | K3: 45931
A4: SKU-004 | B4: Smartwatch Xiaomi Band | C4: Electronics | D4: 30 | E4: 30 | F4: 2 | G4: 7 | H4: SUP_EL01 | I4: 46029 | J4: 1200000 | K4: 46023
A5: SKU-005 | B5: Kemeja Formal Pria | C5: Fashion | D5: 25 | E5: 50 | F5: 6 | G5: 3 | H5: SUP_FA01 | I5: 45688 | J5: 350000 | K5: 45658
A6: SKU-002 | B6: Smartphone Samsung A54 | C6: Electronics | D6: 0 | E6: 25 | F6: 7 | G6: 21 | H6: SUP_EL02 | I6: 45978 | J6: 4500000 | K6: 45962
A7: SKU-005 | B7: Kemeja Formal Pria | C7: Fashion | D7: 0 | E7: 50 | F7: 11 | G7: 7 | H7: SUP_FA01 | I7: 45749 | J7: 350000 | K7: 45748
A8: SKU-007 | B8: Sepatu Sneakers Nike | C8: Fashion | D8: 0 | E8: 35 | F8: 8 | G8: 5 | H8: SUP_FA02 | I8: 45774 | J8: 1250000 | K8: 45748
A9: SKU-013 | B9: Skincare Set Whitelab | C9: Beauty | D9: 220 | E9: 40 | F9: 2 | G9: 5 | H9: SUP_BT01 | I9: 45831 | J9: 550000 | K9: 45809
A10: SKU-018 | B10: Teh Organik Premium Box | C10: Food & Beverage | D10: 28 | E10: 80 | F10: 11 | G10: 4 | H10: SUP_FB01 | I10: 45812 | J10: 65000 | K10: 45809
A11: SKU-004 | B11: Smartwatch Xiaomi Band | C11: Electronics | D11: 24 | E11: 30 | F11: 3 | G11: 6 | H11: SUP_EL01 | I11: 45695 | J11: 1200000 | K11: 45689
A12: SKU-006 | B12: Dress Casual Wanita | C12: Fashion | D12: -28 | E12: 45 | F12: 7 | G12: 5 | H12: SUP_FA01 | I12: 45664 | J12: 450000 | K12: 45658
A13: SKU-011 | B13: Vacuum Cleaner Deerma | C13: Home & Living | D13: -18 | E13: 15 | F13: 4 | G13: 6 | H13: SUP_HM02 | I13: 46099 | J13: 1200000 | K13: 46082
... A76: SKU-002 | B76: Smartphone Samsung A54 | C76: Electronics | D76: 42 | E76: 25 | F76: 4 | G76: 19 | H76: SUP_EL02 | I76: 45881 | J76: 4500000 | K76: 45870
A77: SKU-019 | B77: Madu Hutan Asli 500ml | C77: Food & Beverage | D77: 18 | E77: 60 | F77: 8 | G77: 5 | H77: SUP_FB02 | I77: 45712 | K77: 45689
A78: SKU-004 | B78: Smartwatch Xiaomi Band | C78: Electronics | D78: 17 | E78: 30 | F78: 6 | G78: 8 | H78: SUP_EL01 | I78: 45996 | J78: 1200000 | K78: 45992
A79: SKU-016 | B79: Parfum EDT Brasov 100ml | C79: Beauty | D79: 238 | E79: 50 | F79: 2 | G79: 7 | H79: SUP_BT02 | I79: 45671 | J79: 125000 | K79: 45658
A80: SKU-008 | B80: Tas Ransel Eiger | C80: Fashion | D80: 0 | E80: 40 | F80: 10 | G80: 7 | H80: SUP_FA02 | I80: 46109 | J80: 550000 | K80: 46082
A81: SKU-018 | B81: Teh Organik Premium Box | C81: Food & Beverage | E81: 80 | F81: 11 | G81: 4 | H81: SUP_FB01 | I81: 45766 | J81: 65000 | K81: 45748
A82: SKU-017 | B82: Kopi Arabika 250g Pack | C82: Food & Beverage | D82: 26 | E82: 100 | F82: 16 | G82: 4 | H82: SUP_FB01 | I82: 45778 | J82: 85000 | K82: 45778
A83: SKU-014 | B83: Lipstik Matte Wardah | C83: Beauty | D83: 301 | E83: 80 | F83: 3 | G83: 4 | H83: SUP_BT01 | I83: 45936 | J83: 85000 | K83: 45931
A84: SKU-010 | B84: Rice Cooker Miyako 1.8L | C84: Home & Living | D84: 19 | E84: 25 | F84: 4 | G84: 10 | H84: SUP_HM01 | I84: 45729 | J84: 450000 | K84: 45717
A85: SKU-012 | B85: Kipas Angin Cosmos 16in | C85: Home & Living | D85: 51 | E85: 30 | F85: 6 | G85: 9 | H85: SUP_HM02 | I85: 45752 | J85: 350000 | K85: 45748
A86: SKU-007 | B86: Sepatu Sneakers Nike | C86: Fashion | D86: 17 | E86: 35 | F86: 5 | G86: 5 | H86: SUP_FA02 | I86: 45663 | J86: 1250000 | K86: 45658
A87: SKU-015 | B87: Foundation Maybelline Fit | C87: Beauty | D87: 223 | E87: 60 | F87: 4 | G87: 8 | H87: SUP_BT02 | I87: 46108 | J87: 165000 | K87: 46082
A88: SKU-005 | B88: Kemeja Formal Pria | C88: Fashion | D88: 34 | E88: 50 | F88: 6 | G88: 6 | H88: SUP_FA01 | I88: 45849 | J88: 350000 | K88: 45839
A89: SKU-008 | B89: Tas Ransel Eiger | C89: Fashion | D89: 10 | E89: 40 | F89: 4 | G89: 3 | H89: SUP_FA02 | I89: 46055 | J89: 550000 | K89: 46054
A90: SKU-014 | B90: Lipstik Matte Wardah | C90: Beauty | D90: 436 | E90: 80 | F90: 4 | G90: 4 | H90: SUP_BT01 | I90: 45755 | J90: 85000 | K90: 45748
A91: SKU-002 | B91: Smartphone Samsung A54 | C91: Electronics | D91: 0 | E91: 25 | F91: 8 | G91: 10 | H91: SUP_EL02 | I91: 46013 | J91: 4500000 | K91: 45992
A92: SKU-002 | B92: Smartphone Samsung A54 | C92: Electronics | D92: 20 | E92: 25 | F92: 4 | G92: 19 | H92: SUP_EL02 | I92: 45786 | J92: 4500000 | K92: 45778
A93: SKU-010 | B93: Rice Cooker Miyako 1.8L | C93: Home & Living | D93: 42 | E93: 25 | F93: 4 | G93: 8 | H93: SUP_HM01 | I93: 46029 | J93: 450000 | K93: 46023
... A122: SKU-007 | B122: Sepatu Sneakers Nike | C122: Fashion | D122: 18 | E122: 35 | F122: 7 | G122: 5 | H122: SUP_FA02 | I122: 45859 | J122: 1250000 | K122: 45839
A123: SKU-010 | B123: Rice Cooker Miyako 1.8L | C123: Home & Living | D123: 14 | E123: 25 | F123: 5 | G123: 9 | H123: SUP_HM01 | I123: 45816 | K123: 45809
A124: SKU-012 | B124: Kipas Angin Cosmos 16in | C124: Home & Living | D124: 34 | E124: 30 | F124: 5 | G124: 5 | H124: SUP_HM02 | I124: 46007 | J124: 350000 | K124: 45992
